<?xml version="1.0" encoding="UTF-8"?>
<testsuite name="MapSafeImplTest" tests="1" skipped="0" failures="0" errors="0" timestamp="2023-09-10T15:20:11" hostname="MBP-Danil" time="0.028">
  <properties/>
  <testcase name="mapSafeTest()" classname="MapSafeImplTest" time="0.028"/>
  <system-out><![CDATA[tinkoff.ru
]]></system-out>
  <system-err><![CDATA[[Thread_ONE] INFO org.example.synced.SyncedRepository - Map has been updated, key:value pair added {tinkoff:tinkoff.ru}
[Thread_TWO] INFO org.example.synced.SyncedRepository - Map has NOT been updated, key:value pair NOT added {tinkoff:tinkoff.ru/api/contactless_payments}
Exception in thread "Thread_TWO" java.lang.RuntimeException: This name {tinkoff.ru} has been already used
	at org.example.synced.SyncedRepository.save(SyncedRepository.java:25)
	at org.example.synced.SyncedClient.sendToRepository(SyncedClient.java:11)
	at MapSafeImplTest$2.run(MapSafeImplTest.java:28)
	at java.base/java.lang.Thread.run(Thread.java:829)
]]></system-err>
</testsuite>
