<?xml version="1.0" encoding="UTF-8"?>
<testsuite name="LockTest" tests="1" skipped="0" failures="0" errors="0" timestamp="2023-09-10T14:14:27" hostname="MBP-Danil" time="0.025">
  <properties/>
  <testcase name="locksTest()" classname="LockTest" time="0.025"/>
  <system-out><![CDATA[tinkoff.ru
]]></system-out>
  <system-err><![CDATA[[Thread_ONE] INFO org.example.locks.LockRepository - Map has been updated, key:value pair added {tinkoff:tinkoff.ru}
[Thread_TWO] INFO org.example.locks.LockRepository - Map has NOT been updated, key:value pair NOT added {tinkoff:tinkoff.ru/api/contactless_payments}
Exception in thread "Thread_TWO" java.lang.RuntimeException: This name has been already used
	at org.example.locks.LockRepository.save(LockRepository.java:32)
	at org.example.locks.LockClient.sendToRepository(LockClient.java:15)
	at LockTest$2.run(LockTest.java:29)
	at java.base/java.lang.Thread.run(Thread.java:829)
]]></system-err>
</testsuite>
